---
title: Why there are three best? 
tags:
  - daily work
  - 2022se
categories:
  - diaries
date: 04-15-2023
---
# What I have done today

1. Checked the errors.
    Changed `config.py` because I had reorganize data. (Or there would be errors same to editing with a wrong folder name.)
    
	```
	# TESTING_DATASET_NAME = 'test_data'
	TESTING_DATASET_NAME = 'datasets/test_data'
	```
	And returned path error: `FileNotFoundError: [Errno 2] File /mnt/data/trait/reference/2022se/insects-recognition-main/datasets/datasets/test_data/df_img_meta.csvdoes not exist`.

	There are two `datasets` directories in the path.

	Tried to use absolute path in both `DATASETS_LIST` and `TESTING_DATASET_NAME` in `config.py` and the path error solved. 
	*Significantly, `model_test.py` needs directory `weights` locate at object-home-path and using relative path in `config.py`.*
	
2. New error occurred in `test_model` function with `AssertionError:  `.`test_model` was import from `model_test.py` and error occurred at line 180 which is caused by `assert` function. 
      Error message:
	```
	--------------------------------------------------------------------------- 
	AssertionError Traceback (most recent call last) 
	in 
	18 print(config.TESTING_DATASET_NAME) 
	19 test_model(model_name=config.TESTING_MODEL_NAME, dataset_name=config.TESTING_DATASET_NAME,
---> 20 folder_to_evaluate=folder_name, model_type=mtype) 
	 21 if config.TESTING_INTERPRETABLE_PLOTS: 
	 22 make_interpretable_plots(model_name=config.TESTING_MODEL_NAME,
   
   /mnt/data/trait/reference/2022se/insects-recognition-main/src/models_test.py
	 in 
	 test_model(model_name, dataset_name, folder_to_evaluate, model_type) 
	 178 # Формирование табличного отчета по качеству классфикации 
	 179 # Для объективной оценки испольузем только лучшую эпоху по валидации. 
---> 180 assert len(reports_list) == 1 
	181 report_dict = reports_list[0] 
	182 df_detailed_report = pd.DataFrame([]) AssertionError: 
	```
	
	The comments in line 178 and 179 said that we need a best something, namely the length of `reprots_list` must be 1 or occurred this error.

	Check variable `reports_list` in `models_test.py`. 
	```
	EVAL_DICT = {'device': DEVICE,
	'weights_folder': weights_folder,
	'test_loader': test_data_loader,
	'model': nnet,
	'criterion': torch.nn.CrossEntropyLoss(),
	'target_names': list(TRAIN_DATASET_KWARGS['class_dict'].keys()),
	'class_dict': CLASS_DICT,
	'data_hash': train_data_hash,
	'external_data_class_dict': None,
	
	reports_list = model_evaluate(EVAL_DICT)
	```
	 Check function `model_evaluate` in `./utils/model_test_utils.py`.
	```
	def model_evaluate(evaluate_dict):
	weights_folder = evaluate_dict['weights_folder']
	weights_list = [os.path.join(weights_folder, x) for x in os.listdir(weights_folder) if '.pth' in x]
	epoch_dict = dict([(int(x.split('.')[0].split('_')[-1]), x) for x in weights_list])
	sorted_epochs = sorted(epoch_dict)
	reports_list = []
	for epoch in tqdm.tqdm(sorted_epochs):
		weights_path = epoch_dict[epoch]
		print('Epoch: ', epoch)
		print('Weights path: ', weights_path)
		if evaluate_dict['external_data_class_dict']:
			report_dict = eval_epoch_on_external_data(weights_path, evaluate_dict)
		else:
			report_dict = eval_epoch(weights_path, evaluate_dict)
		report_dict.update({'epoch': epoch})
		reports_list.append(report_dict)
	return reports_list
	```
	Check the length of `reports_list` in `for` by adding `print(len(reports_list))` and found that the length grew up to 3 from 1 caused by `reports_list.append(report_dict)`. 
# What I need to do next

1. Find out how `append` works and why use it. How to make it correct. 
